<?xml version="1.0" ?>
<robot name="turtlebot3_waffle" xmlns:xacro="http://ros.org/wiki/xacro">
  <xacro:include filename="$(find covid_robot_description)/urdf/covid_robot.gazebo.xacro"/>

  <xacro:property name="r200_cam_rgb_px" value="0.005"/>
  <xacro:property name="r200_cam_rgb_py" value="0.018"/>
  <xacro:property name="r200_cam_rgb_pz" value="0.013"/>
  <xacro:property name="r200_cam_depth_offset" value="0.01"/>

  <link name="base_footprint"/>

  <joint name="base_joint" type="fixed">
    <parent link="base_footprint"/>
    <child link="base_link" />
    <origin xyz="0 0 0.010" rpy="0 0 -1.57"/>
  </joint>

  <link name="base_link">
    <visual>
      <origin xyz="0.0 0 0.25" rpy="0 0 0.0"/>
      <geometry>
        <mesh filename="package://covid_robot_description/meshes/bases/covid_robot_body.stl" scale="0.001 0.001 0.001"/>
      </geometry>
      <material name="black"/>
    </visual>

    <collision>
      <origin xyz="0 0 0.047" rpy="0 0 0"/>
      <geometry>
        <box size="0.266 0.266 0.094"/>
      </geometry>
    </collision>
  </link>

  <joint name="wheel_right_joint_1_steer" type="fixed">
    <parent link="base_link"/>
    <child link="wheel_right_link_1_steer"/>
    <!-- if error => z = -0.03 -->
    <origin xyz="-0.4 0.22 -0.08" rpy="0 0 0"/>
  </joint>

  <link name="wheel_right_link_1_steer">
    <visual>
      <origin xyz="0 0 0.1" rpy="1.57 0 0"/>
      <geometry>
        <mesh filename="package://covid_robot_description/meshes/wheels/steering_motor.stl" scale="0.001 0.001 0.001"/>
      </geometry>
      <material name="dark"/>
    </visual>

    <collision>
      <origin xyz="0 0 0" rpy="0 0 0"/>
    </collision>
  </link>

  <joint name="wheel_right_joint_1" type="continuous">
    <parent link="base_link"/>
    <child link="wheel_right_link_1"/>
    <!-- x = -0.45 -->
    <origin xyz="-0.48 0.22 0.023" rpy="0 -1.57 0"/>
    <axis xyz="0 0 1"/>
  </joint>

  <link name="wheel_right_link_1">
    <visual>
      <origin xyz="0.0 0 0.02" rpy="1.57 0 0"/>
      <geometry>
        <mesh filename="package://covid_robot_description/meshes/wheels/covid_robot_tire.stl" scale="0.001 0.001 0.001"/>
      </geometry>
      <material name="dark"/>
    </visual>

    <collision>
      <origin xyz="0 0 0" rpy="0 0 0"/>
      <geometry>
        <cylinder length="0.018" radius="0.1"/>
      </geometry>
    </collision>

    <inertial>
      <origin xyz="0 0 0" />
      <mass value="2.8498940e-02" />
      <inertia ixx="1.1175580e-05" ixy="-4.2369783e-11" ixz="-5.9381719e-09"
               iyy="1.1192413e-05" iyz="-1.4400107e-11"
               izz="2.0712558e-05" />
    </inertial>
  </link>

  
  <joint name="wheel_left_joint_1_steer" type="fixed">
    <parent link="base_link"/>
    <child link="wheel_left_link_1_steer"/>
    <origin xyz="0.40 0.22 -0.08" rpy="0 0 0"/>
  </joint>

  <link name="wheel_left_link_1_steer">
      <visual>
      <origin xyz="0 0 0.1" rpy="1.57 0 0"/>
      <geometry>
        <mesh filename="package://covid_robot_description/meshes/wheels/steering_motor.stl" scale="0.001 0.001 0.001"/>
      </geometry>
      <material name="dark"/>
    </visual>

    <collision>
      <origin xyz="0 0 0" rpy="0 0 0"/>
    </collision>

  </link>

  <joint name="wheel_left_joint_1" type="continuous">
    <parent link="base_link"/>
    <child link="wheel_left_link_1"/>
    <origin xyz="0.48 0.22 0.023" rpy="0 -1.57 0"/>
    <axis xyz="0 0 1"/>
  </joint>

  <link name="wheel_left_link_1">
    <visual>
      <origin xyz="0 0 0.02" rpy="1.57 0 0"/>
      <geometry>
        <mesh filename="package://covid_robot_description/meshes/wheels/covid_robot_tire.stl" scale="0.001 0.001 0.001"/>
      </geometry>
      <material name="dark"/>
    </visual>

    <collision>
      <origin xyz="0 0 0" rpy="0 0 0"/>
      <geometry>
        <cylinder length="0.018" radius="0.1"/>
      </geometry>
    </collision>

    <inertial>
      <origin xyz="0 0 0" />
      <mass value="2.8498940e-02" />
      <inertia ixx="1.1175580e-05" ixy="-4.2369783e-11" ixz="-5.9381719e-09"
               iyy="1.1192413e-05" iyz="-1.4400107e-11"
               izz="2.0712558e-05" />
      </inertial>
  </link>

  <joint name="wheel_left_joint_steer" type="fixed">
    <parent link="base_link"/>
    <child link="wheel_left_link_steer"/>
    <origin xyz="0.40 -0.22 -0.08" rpy="0 0 0"/>
  </joint>

  <link name="wheel_left_link_steer">
    <visual>
      <origin xyz="0 0 0.1" rpy="1.57 0 0"/>
      <geometry>
        <mesh filename="package://covid_robot_description/meshes/wheels/steering_motor.stl" scale="0.001 0.001 0.001"/>
      </geometry>
      <material name="dark"/>
    </visual>

    <collision>
      <origin xyz="0 0 0" rpy="0 0 0"/>
    </collision>
  </link>

  <joint name="wheel_left_joint" type="continuous">
    <parent link="base_link"/>
    <child link="wheel_left_link"/>
    <origin xyz="0.48 -0.22 0.023" rpy="0 -1.57 0"/>
    <axis xyz="0 0 1"/>
  </joint>

  <link name="wheel_left_link">
    <visual>
      <origin xyz="0.0 0 0.02" rpy="1.57 0 0"/>
      <geometry>
        <mesh filename="package://covid_robot_description/meshes/wheels/covid_robot_tire.stl" scale="0.001 0.001 0.001"/>
      </geometry>
      <material name="dark"/>
    </visual>

    <collision>
      <origin xyz="0 0 0" rpy="0 0 0"/>
      <geometry>
        <cylinder length="0.018" radius="0.1"/>
      </geometry>
    </collision>

    <inertial>
      <origin xyz="0 0 0" />
      <mass value="2.8498940e-02" />
      <inertia ixx="1.1175580e-05" ixy="-4.2369783e-11" ixz="-5.9381719e-09"
               iyy="1.1192413e-05" iyz="-1.4400107e-11"
               izz="2.0712558e-05" />
      </inertial>
  </link>

  
  <joint name="wheel_right_joint_steer" type="fixed">
    <parent link="base_link"/>
    <child link="wheel_right_link_steer"/>
    <origin xyz="-0.40 -0.22 -0.08" rpy="0 0 0"/>
  </joint>

  <link name="wheel_right_link_steer">
    <visual>
      <origin xyz="0 0 0.1" rpy="1.57 0 0"/>
      <geometry>
        <mesh filename="package://covid_robot_description/meshes/wheels/steering_motor.stl" scale="0.001 0.001 0.001"/>
      </geometry>
      <material name="dark"/>
    </visual>

    <collision>
      <origin xyz="0 0 0" rpy="0 0 0"/>
    </collision>

  </link>

  <joint name="wheel_right_joint" type="continuous">
    <parent link="base_link"/>
    <child link="wheel_right_link"/>
    <origin xyz="-0.48 -0.22 0.023" rpy="0 -1.57 0"/>
    <axis xyz="0 0 1"/>
  </joint>

  <link name="wheel_right_link">
    <visual>
      <origin xyz="0 0 0.02" rpy="1.57 0 0"/>
      <geometry>
        <mesh filename="package://covid_robot_description/meshes/wheels/covid_robot_tire.stl" scale="0.001 0.001 0.001"/>
      </geometry>
    </visual>

    <collision>
      <origin xyz="0 0 0" rpy="0 0 0"/>
      <geometry>
        <cylinder length="0.018" radius="0.1"/>
      </geometry>
    </collision>

    <inertial>
      <origin xyz="0 0 0" />
      <mass value="2.8498940e-02" />
      <inertia ixx="1.1175580e-05" ixy="-4.2369783e-11" ixz="-5.9381719e-09"
               iyy="1.1192413e-05" iyz="-1.4400107e-11"
               izz="2.0712558e-05" />
      </inertial>
  </link>

  <joint name="body_side_left_rack" type="fixed">
    <parent link="base_link"/>
    <child link="body_side_left_rack"/>
    <!-- x = -0.45 when opened -->
    <origin xyz="-0.45 0.0 0.9" rpy="0 0 0"/> 
  </joint>

  <link name="body_side_left_rack">
    <visual>
      <origin xyz="0.0 0.0 0.0" rpy="0 -1.65 0"/>
      <geometry>
        <mesh filename="package://covid_robot_description/meshes/bases/body_side_rack.stl" scale="0.001 0.001 0.001"/>
      </geometry>
      <material name="dark"/>
    </visual>

    <collision>
      <origin xyz="0 0 0" rpy="0 0 0"/>
    </collision>
  </link>

  <joint name="body_side_right_rack" type="fixed">
    <parent link="base_link"/>
    <child link="body_side_right_rack"/>
    <!-- x = 0.45 when opened -->
    <origin xyz="0.45 0.0 0.9" rpy="0 0 0"/> 
  </joint>

  <link name="body_side_right_rack">
    <visual>
      <origin xyz="0.0 0.0 0.0" rpy="0 -1.65 0"/>
      <geometry>
        <mesh filename="package://covid_robot_description/meshes/bases/body_side_rack.stl" scale="0.001 0.001 0.001"/>
      </geometry>
      <material name="dark"/>
    </visual>

    <collision>
      <origin xyz="0 0 0" rpy="0 0 0"/>
    </collision>
  </link>

  <joint name="body_side_left" type="fixed">
    <parent link="base_link"/>
    <child link="body_side_left"/>
    <!-- x = -0.45 when closed -->
    <!-- x = -0.75 when opened -->
    <origin xyz="-0.45 0.0 0.460" rpy="0 0 0"/> 
  </joint>

  <link name="body_side_left">
    <visual>
      <origin xyz="0.0 0.0 0.1" rpy="1.57 0 0"/>
      <geometry>
        <mesh filename="package://covid_robot_description/meshes/bases/body_side.stl" scale="0.001 0.001 0.001"/>
      </geometry>
      <material name="dark"/>
    </visual>

    <collision>
      <origin xyz="0 0 0" rpy="0 0 0"/>
    </collision>
  </link>


  <joint name="body_side_right" type="fixed">
    <parent link="base_link"/>
    <child link="body_side_right"/>
    <!-- x = 0.45 when closed -->
    <!-- x = 0.75 when opened -->
    <origin xyz="0.45 0.0 0.460" rpy="0 0 0"/>
  </joint>

  

  <link name="body_side_right">
    <visual>
      <origin xyz="0.0 0.0 0.1" rpy="1.57 0 -3.14"/>
      <geometry>
        <mesh filename="package://covid_robot_description/meshes/bases/body_side.stl" scale="0.001 0.001 0.001"/>
      </geometry>
    </visual>

    <collision>
      <origin xyz="0 0 0" rpy="0 0 0"/>
    </collision>
  </link>

  <!-- <joint name="left_cleaning" type="fixed">
    <parent link="base_link"/>
    <child link="left_cleaning"/>
    <origin xyz="-0.9 0.1 .5" rpy="0 0 0"/> 
  </joint>

  <link name="left_cleaning">
    <visual>
      <origin xyz="0.0 0.0 0.0" rpy="1.57 0 0"/>
      <geometry>
        <mesh filename="package://covid_robot_description/meshes/bases/cleaning.stl" scale="0.001 0.001 0.001"/>
      </geometry>
      <material name="dark"/>
    </visual>

    <collision>
      <origin xyz="0 0 0" rpy="0 0 0"/>
    </collision>
  </link>

  <joint name="right_cleaning" type="fixed">
    <parent link="base_link"/>
    <child link="right_cleaning"/>
    <origin xyz="0.65 0.1 0.5" rpy="1.57 0 0"/> 
  </joint>

  <link name="right_cleaning">
    <visual>
      <origin xyz="0.0 0.0 0.0" rpy="0 0 0"/>
      <geometry>
        <mesh filename="package://covid_robot_description/meshes/bases/cleaning.stl" scale="0.001 0.001 0.001"/>
      </geometry>
      <material name="dark"/>
    </visual>

    <collision>
      <origin xyz="0 0 0" rpy="0 0 0"/>
    </collision>
  </link> -->

  <joint name="imu_joint" type="fixed">
    <parent link="base_link"/>
    <child link="imu_link"/>
    <origin xyz="0.0 0 0.068" rpy="0 0 0"/>
  </joint>

  <link name="imu_link"/>

  <joint name="scan_joint" type="fixed">
    <parent link="base_link"/>
    <child link="base_scan"/>
    <origin xyz="0.0 0 0.2" rpy="0 0 1.57"/>
  </joint>

  <link name="base_scan">
    <visual>
      <origin xyz="0 0 0" rpy="0 0 0"/>
      <geometry>
        <mesh filename="package://turtlebot3_description/meshes/sensors/lds.stl" scale="0.001 0.001 0.001"/>
      </geometry>
      <material name="dark"/>
    </visual>

    <collision>
      <origin xyz="0.015 0 -0.0065" rpy="0 0 0"/>
      <geometry>
        <cylinder length="0.0315" radius="0.055"/>
      </geometry>
    </collision>

    <inertial>
      <mass value="0.114" />
      <origin xyz="0 0 0" />
      <inertia ixx="0.001" ixy="0.0" ixz="0.0"
               iyy="0.001" iyz="0.0"
               izz="0.001" />
    </inertial>
  </link>


  <joint name="camera_joint" type="fixed">
    <!-- <origin xyz="0.073 -0.011 0.084" rpy="0 0 0"/> -->
    <origin xyz="0.0 0.8 0.8" rpy="0 0 1.57"/>
    <parent link="base_link"/>
    <child link="camera_link"/>
  </joint>

  <link name="camera_link">
    <collision>
      <origin xyz="0.005 0.0 0.5" rpy="0 0 0"/>
      <geometry>
        <box size="0.015 0.030 0.027"/>
      </geometry>
    </collision>
  </link>

  <joint name="camera_rgb_joint" type="fixed">
    <origin xyz="1.0 0.0 0.0" rpy="0 0 0"/>
    <parent link="camera_link"/>
    <child link="camera_rgb_frame"/>
  </joint>
  <link name="camera_rgb_frame"/>

  <joint name="camera_rgb_optical_joint" type="fixed">
    <origin xyz="0 0 0" rpy="-1.57 0 -1.57"/>
    <parent link="camera_rgb_frame"/>
    <child link="camera_rgb_optical_frame"/>
  </joint>
  <link name="camera_rgb_optical_frame"/>
</robot>
